Workbook

Sheet كشف
B1: قائمة بالعماله الخارجية
B4: م | C4: الاسم | D4: الاقامه | E4: تاريخ الحساب | F4: السيارة | G4: اخر تاريخ سداد | H4: من طرف | I4: أشهر متأخرة | J4: عمود2 | K4: دائن خدمات | L4: مدين خدمات | M4: رصيد خدمات | N4: عمود1 | O4: دائن مستحقات | P4: مدين مستحقات | Q4: رصيد مستحقات | R4: عمود3 | S4: ملاحظات التواصل
B5: 1 | C5: ='1'!B2 -> محمد احمد اطرش | D5: ='1'!B4 -> 2275610844 | E5: ='1'!E4 -> 44181 | F5: ='1'!B6 -> 0 | G5: ='1'!H6 -> 44181 | H5: ='1'!H4 -> ابوبيان | I5: =(TODAY()-الجدول3[[#This Row],[اخر تاريخ سداد]])/30 -> 59.866667 | K5: =SUM('1'!K54:K107) -> 40900 | L5: =SUM('1'!L54:L108) -> 41529 | M5: =الجدول3[[#This Row],[دائن خدمات]]-الجدول3[[#This Row],[مدين خدمات]] -> -629 | O5: =SUM('1'!O12:O108) -> 0 | P5: =SUM('1'!P12:P108) -> 5000 | Q5: =الجدول3[[#This Row],[دائن مستحقات]]-الجدول3[[#This Row],[مدين مستحقات]] -> -5000
B6: 6 | C6: ='6'!B2 -> أسامة الأشقر | D6: ='6'!B4 -> 2270223429 | E6: ='6'!E4 -> 45057 | F6: ='6'!B6 -> 0 | G6: ='6'!H6 -> 45110 | H6: ='6'!H4 -> محمد اطرش | I6: =(TODAY()-الجدول3[[#This Row],[اخر تاريخ سداد]])/30 -> 28.9 | K6: =SUM('6'!K12:K113) -> 61185 | L6: =SUM('6'!L12:L113) -> 58285 | M6: =الجدول3[[#This Row],[دائن خدمات]]-الجدول3[[#This Row],[مدين خدمات]] -> 2900 | O6: =SUM('6'!O12:O115) -> 12300 | P6: =SUM('6'!P12:P115) -> 27800 | Q6: =الجدول3[[#This Row],[دائن مستحقات]]-الجدول3[[#This Row],[مدين مستحقات]] -> -15500 | S6: متأخر تحت التواصل
B7: 7 | C7: ='7'!B2 -> عبدالرزاق أحمد | D7: ='7'!B4 -> 2244421182 | E7: ='7'!E4 -> 44740 | F7: ='7'!B6 -> 6972 | G7: ='7'!H6 -> 45809 | H7: ='7'!H4 -> محمد اطرش | I7: =(TODAY()-الجدول3[[#This Row],[اخر تاريخ سداد]])/30 -> 5.6 | K7: =SUM('7'!K12:K115) -> 43147 | L7: =SUM('7'!L12:L115) -> 43097 | M7: =الجدول3[[#This Row],[دائن خدمات]]-الجدول3[[#This Row],[مدين خدمات]] -> 50 | O7: =SUM('7'!O12:O117) -> 28900 | P7: =SUM('7'!P12:P117) -> 33600 | Q7: =الجدول3[[#This Row],[دائن مستحقات]]-الجدول3[[#This Row],[مدين مستحقات]] -> -4700 | S7: متأخر تحت التواصل
B8: 8 | C8: ='8'!B2 -> اديب محمد | D8: ='8'!B4 -> 2305927978 | E8: ='8'!E4 -> 44765 | F8: ='8'!B6 -> 1527 | G8: ='8'!H6 -> 45839 | H8: ='8'!H4 -> محمد اطرش | I8: =(TODAY()-الجدول3[[#This Row],[اخر تاريخ سداد]])/30 -> 4.6 | K8: =SUM('8'!K12:K115) -> 57553 | L8: =SUM('8'!L12:L115) -> 56296 | M8: =الجدول3[[#This Row],[دائن خدمات]]-الجدول3[[#This Row],[مدين خدمات]] -> 1257 | O8: =SUM('8'!O12:O117) -> 30850 | P8: =SUM('8'!P12:P117) -> 33600 | Q8: =الجدول3[[#This Row],[دائن مستحقات]]-الجدول3[[#This Row],[مدين مستحقات]] -> -2750
B9: 9 | C9: ='9'!B2 -> عصام الريح | D9: ='9'!B4 -> 2133835989 | E9: ='9'!E4 -> 44712 | F9: ='9'!B6 -> 3656 - 4383 | G9: ='9'!H6 -> 44712 | H9: ='9'!H4 -> ابوبيان | I9: =(TODAY()-الجدول3[[#This Row],[اخر تاريخ سداد]])/30 -> 42.166667 | K9: =SUM('9'!K12:K117) -> 22300 | L9: =SUM('9'!L12:L117) -> 535 | M9: =الجدول3[[#This Row],[دائن خدمات]]-الجدول3[[#This Row],[مدين خدمات]] -> 21765 | O9: =SUM('9'!O12:O119) -> 13100 | P9: =SUM('9'!P12:P119) -> 39000 | Q9: =الجدول3[[#This Row],[دائن مستحقات]]-الجدول3[[#This Row],[مدين مستحقات]] -> -25900
B10: 10 | C10: ='10'!B2 -> سالم الحميدي | D10: ='10'!B4 -> 2244737371 | E10: ='10'!E4 -> 44585 | F10: ='10'!B6 -> 3010 / 8827 | G10: ='10'!H6 -> 45778 | H10: ='10'!H4 -> أبو عبدالله السوري | I10: =(TODAY()-الجدول3[[#This Row],[اخر تاريخ سداد]])/30 -> 6.6333333 | K10: =SUM('10'!K12:K118) -> 6850 | L10: =SUM('10'!L12:L118) -> 6850 | M10: =الجدول3[[#This Row],[دائن خدمات]]-الجدول3[[#This Row],[مدين خدمات]] -> 0 | O10: =SUM('10'!O12:O120) -> 20100 | P10: =SUM('10'!P12:P120) -> 23800 | Q10: =الجدول3[[#This Row],[دائن مستحقات]]-الجدول3[[#This Row],[مدين مستحقات]] -> -3700
B11: 11 | C11: ='11'!B3 -> عبده دقماق | D11: ='11'!B5 -> 2304733724 | E11: ='11'!E5 -> 44594 | F11: ='11'!B7 -> 5019 | G11: ='11'!H7 -> 45746 | H11: ='11'!H5 -> محمد اطرش | I11: =(TODAY()-الجدول3[[#This Row],[اخر تاريخ سداد]])/30 -> 7.7 | K11: =SUM('11'!K13:K120) -> 6500 | L11: =SUM('11'!L13:L120) -> 6500 | M11: =الجدول3[[#This Row],[دائن خدمات]]-الجدول3[[#This Row],[مدين خدمات]] -> 0 | O11: =SUM('11'!O12:O121) -> 15500 | P11: =SUM('11'!P12:P121) -> 15500 | Q11: =الجدول3[[#This Row],[دائن مستحقات]]-الجدول3[[#This Row],[مدين مستحقات]] -> 0 | S11: منتظم
B12: 15 | C12: ='15'!B2 -> محمد مثنى | D12: ='15'!B4 -> 2036474902 | E12: ='15'!E4 -> 45071 | F12: ='15'!B6 -> 0 | G12: ='15'!H6 -> 45897 | H12: ='15'!H4 -> فيصل رمضان | I12: =(TODAY()-الجدول3[[#This Row],[اخر تاريخ سداد]])/30 -> 2.6666667 | K12: =SUM('15'!K12:K123) -> 17200 | L12: =SUM('15'!L12:L123) -> 17200 | M12: =الجدول3[[#This Row],[دائن خدمات]]-الجدول3[[#This Row],[مدين خدمات]] -> 0 | O12: =SUM('15'!O12:O125) -> 37000 | P12: =SUM('15'!P12:P125) -> 44000 | Q12: =الجدول3[[#This Row],[دائن مستحقات]]-الجدول3[[#This Row],[مدين مستحقات]] -> -7000
B13: 18 | C13: ='18'!B2 -> مرعي بركات | D13: ='18'!B4 -> 2310964073 | E13: ='18'!E4 -> 45067 | F13: ='18'!B6 -> 3228 | G13: ='18'!H6 -> 44624 | H13: ='18'!H4 -> مهند | I13: =(TODAY()-الجدول3[[#This Row],[اخر تاريخ سداد]])/30 -> 45.1 | K13: =SUM('18'!K12:K126) -> 69700 | L13: =SUM('18'!L12:L126) -> 69643 | M13: =الجدول3[[#This Row],[دائن خدمات]]-الجدول3[[#This Row],[مدين خدمات]] -> 57 | O13: =SUM('18'!O12:O128) -> 0 | P13: =SUM('18'!P12:P128) -> 33600 | Q13: =الجدول3[[#This Row],[دائن مستحقات]]-الجدول3[[#This Row],[مدين مستحقات]] -> -33600 | S13: متأخر تحت التواصل
B14: 19 | C14: ='19'!B2 -> عماد التقي | D14: ='19'!B4 -> 2266992110 | E14: ='19'!E4 -> 45267 | F14: ='19'!B6 -> 2672 | G14: ='19'!H6 -> 44978 | H14: ='19'!H4 -> ابوبيان | I14: =(TODAY()-الجدول3[[#This Row],[اخر تاريخ سداد]])/30 -> 33.3 | K14: =SUM('19'!K12:K127) -> 28195 | L14: =SUM('19'!L12:L127) -> 29295 | M14: =الجدول3[[#This Row],[دائن خدمات]]-الجدول3[[#This Row],[مدين خدمات]] -> -1100 | O14: =SUM('19'!O12:O129) -> 5000 | P14: =SUM('19'!P12:P129) -> 33600 | Q14: =الجدول3[[#This Row],[دائن مستحقات]]-الجدول3[[#This Row],[مدين مستحقات]] -> -28600 | S14: متأخر تحت التواصل
B15: 20 | C15: ='20'!B2 -> محمد الأحمد | D15: ='20'!B4 -> 2248778017 | E15: ='20'!E4 -> 44594 | F15: ='20'!B6 -> 3597 | G15: ='20'!H6 -> 45658 | H15: ='20'!H4 -> أبو عبدالله السوري | I15: =(TODAY()-الجدول3[[#This Row],[اخر تاريخ سداد]])/30 -> 10.633333 | K15: =SUM('20'!K12:K128) -> 8915 | L15: =SUM('20'!L12:L128) -> 8915 | M15: =الجدول3[[#This Row],[دائن خدمات]]-الجدول3[[#This Row],[مدين خدمات]] -> 0 | O15: =SUM('20'!O12:O130) -> 14200 | P15: =SUM('20'!P12:P130) -> 15600 | Q15: =الجدول3[[#This Row],[دائن مستحقات]]-الجدول3[[#This Row],[مدين مستحقات]] -> -1400
B16: 21 | C16: ='21'!B2 -> مروان ياسين | D16: ='21'!B4 -> 2267184402 | E16: ='21'!E4 -> 44886 | F16: ='21'!B6 -> 6787 | G16: ='21'!H6 -> 45962 | H16: ='21'!H4 -> محمد اطرش | I16: =(TODAY()-الجدول3[[#This Row],[اخر تاريخ سداد]])/30 -> 0.5 | K16: =SUM('21'!K12:K128) -> 60900 | L16: =SUM('21'!L12:L128) -> 61017 | M16: =الجدول3[[#This Row],[دائن خدمات]]-الجدول3[[#This Row],[مدين خدمات]] -> -117 | O16: =SUM('21'!O12:O130) -> 26900 | P16: =SUM('21'!P12:P130) -> 25200 | Q16: =الجدول3[[#This Row],[دائن مستحقات]]-الجدول3[[#This Row],[مدين مستحقات]] -> 1700 | S16: متأخر تحت التواصل
B17: 22 | C17: ='22'!B2 -> مصطفى يوسف | D17: ='22'!B4 -> 2219684467 | E17: ='22'!E4 -> 44840 | F17: ='22'!B6 -> 1140 | G17: ='22'!H6 -> 44949 | H17: ='22'!H4 -> عبدالرزاق حيلاني | I17: =(TODAY()-الجدول3[[#This Row],[اخر تاريخ سداد]])/30 -> 34.266667 | K17: =SUM('22'!K12:K130) -> 19150 | L17: =SUM('22'!L12:L130) -> 18850 | M17: =الجدول3[[#This Row],[دائن خدمات]]-الجدول3[[#This Row],[مدين خدمات]] -> 300 | O17: =SUM('22'!O12:O132) -> 3400 | P17: =SUM('22'!P12:P132) -> 9600 | Q17: =الجدول3[[#This Row],[دائن مستحقات]]-الجدول3[[#This Row],[مدين مستحقات]] -> -6200 | S17: متأخر تحت التواصل
B18: 24 | C18: ='24'!B2 -> عز الدين المسالمه | D18: ='24'!B4 -> 2279835793 | E18: ='24'!E4 -> 44733 | F18: ='24'!B6 -> 5786 | G18: ='24'!H6 -> 45539 | H18: ='24'!H4 -> ابوبيان | I18: =(TODAY()-الجدول3[[#This Row],[اخر تاريخ سداد]])/30 -> 14.6 | K18: =SUM('24'!K12:K132) -> 5855 | L18: =SUM('24'!L12:L132) -> 5855 | M18: =الجدول3[[#This Row],[دائن خدمات]]-الجدول3[[#This Row],[مدين خدمات]] -> 0 | O18: =SUM('24'!O12:O134) -> 16150 | P18: =SUM('24'!P12:P134) -> 16150 | Q18: =الجدول3[[#This Row],[دائن مستحقات]]-الجدول3[[#This Row],[مدين مستحقات]] -> 0 | S18: تم انهاء العلاقة
B19: 26 | C19: ='26'!B2 -> نضال محمد | D19: ='26'!B4 -> 2318009293 | E19: ='26'!E4 -> 44922 | F19: ='26'!B6 -> - | G19: ='26'!H6 -> 45333 | H19: ='26'!H4 -> مهند | I19: =(TODAY()-الجدول3[[#This Row],[اخر تاريخ سداد]])/30 -> 21.466667 | K19: =SUM('26'!K12:K134) -> 0 | L19: =SUM('26'!L12:L134) -> 1500 | M19: =الجدول3[[#This Row],[دائن خدمات]]-الجدول3[[#This Row],[مدين خدمات]] -> -1500 | O19: =SUM('26'!O12:O136) -> 10000 | P19: =SUM('26'!P12:P136) -> 14400 | Q19: =الجدول3[[#This Row],[دائن مستحقات]]-الجدول3[[#This Row],[مدين مستحقات]] -> -4400 | S19: متأخر - موضوعه مع ابوبيان
B20: 27 | C20: ='27'!B2 -> بابو هندي | D20: ='27'!B4 -> 0 | E20: ='27'!E4 -> 0 | F20: ='27'!B6 -> - | G20: ='27'!H6 -> 44712 | H20: ='27'!H4 -> ابوبيان | I20: =(TODAY()-الجدول3[[#This Row],[اخر تاريخ سداد]])/30 -> 42.166667 | K20: =SUM('27'!K12:K136) -> 18826 | L20: =SUM('27'!L12:L136) -> 18826 | M20: =الجدول3[[#This Row],[دائن خدمات]]-الجدول3[[#This Row],[مدين خدمات]] -> 0 | O20: =SUM('27'!O12:O137) -> 0 | P20: =SUM('27'!P12:P137) -> 3200 | Q20: =الجدول3[[#This Row],[دائن مستحقات]]-الجدول3[[#This Row],[مدين مستحقات]] -> -3200 | S20: متأخر - موضوعه مع ابوبيان
B21: 29 | C21: ='29'!B2 -> احمد حجازي | D21: ='29'!B4 -> 2314453362 | E21: ='29'!E4 -> 44844 | F21: ='29'!B6 -> 3462 | G21: ='29'!H6 -> 45809 | H21: ='29'!H4 -> مهند | I21: =(TODAY()-الجدول3[[#This Row],[اخر تاريخ سداد]])/30 -> 5.6 | K21: =SUM('29'!K12:K137) -> 1900 | L21: =SUM('29'!L12:L137) -> 1900 | M21: =الجدول3[[#This Row],[دائن خدمات]]-الجدول3[[#This Row],[مدين خدمات]] -> 0 | O21: =SUM('29'!O12:O138) -> 13200 | P21: =SUM('29'!P12:P138) -> 19200 | Q21: =الجدول3[[#This Row],[دائن مستحقات]]-الجدول3[[#This Row],[مدين مستحقات]] -> -6000 | S21: تحت التواصل
B22: 30 | C22: ='30'!B2 -> غسان سريا | D22: ='30'!B4 -> 2264376852 | E22: ='30'!E4 -> 0 | F22: ='30'!B6 -> 0 | G22: ='30'!H6 -> 45746 | H22: ='30'!H4 -> نفسه | I22: =(TODAY()-الجدول3[[#This Row],[اخر تاريخ سداد]])/30 -> 7.7 | K22: =SUM('30'!K12:K139) -> 4250 | L22: =SUM('30'!L12:L139) -> 4250 | M22: =الجدول3[[#This Row],[دائن خدمات]]-الجدول3[[#This Row],[مدين خدمات]] -> 0 | O22: =SUM('30'!O12:O140) -> 12000 | P22: =SUM('30'!P12:P140) -> 14400 | Q22: =الجدول3[[#This Row],[دائن مستحقات]]-الجدول3[[#This Row],[مدين مستحقات]] -> -2400 | S22: متأخر - موضوعه مع ابوبيان
B23: 31 | C23: ='31'!B2 -> علي يمني | D23: ='31'!B4 -> 2500370966 | E23: ='31'!E4 -> 0 | F23: ='31'!B6 -> 3606 | G23: ='31'!H6 -> 45658 | H23: ='31'!H4 -> محمود درويش | I23: =(TODAY()-الجدول3[[#This Row],[اخر تاريخ سداد]])/30 -> 10.633333 | K23: =SUM('31'!K12:K140) -> 1650 | L23: =SUM('31'!L12:L140) -> 1575 | M23: =الجدول3[[#This Row],[دائن خدمات]]-الجدول3[[#This Row],[مدين خدمات]] -> 75 | O23: =SUM('31'!O12:O141) -> 13700 | P23: =SUM('31'!P12:P141) -> 14400 | Q23: =الجدول3[[#This Row],[دائن مستحقات]]-الجدول3[[#This Row],[مدين مستحقات]] -> -700
B24: 32 | C24: ='32'!B2 -> مازن مقبل | D24: ='32'!B4 -> 2265016549 | E24: ='32'!E4 -> 0 | F24: ='32'!B6 -> 3599 | G24: ='32'!H6 -> 45870 | H24: ='32'!H4 -> ياسر مقبل 0552379915 | I24: =(TODAY()-الجدول3[[#This Row],[اخر تاريخ سداد]])/30 -> 3.5666667 | K24: =SUM('32'!K12:K141) -> 5085 | L24: =SUM('32'!L12:L141) -> 5535 | M24: =الجدول3[[#This Row],[دائن خدمات]]-الجدول3[[#This Row],[مدين خدمات]] -> -450 | O24: =SUM('32'!O12:O142) -> 11500 | P24: =SUM('32'!P12:P142) -> 13300 | Q24: =الجدول3[[#This Row],[دائن مستحقات]]-الجدول3[[#This Row],[مدين مستحقات]] -> -1800 | S24: تحت التواصل
B25: 33 | C25: ='33'!B2 -> أبو عبدالرحمن | D25: ='33'!B4 -> 2224029344 | E25: ='33'!E4 -> 0 | F25: ='33'!B6 -> 5645 / 9109 | G25: ='33'!H6 -> 0 | H25: ='33'!H4 -> نفسه | I25: =(TODAY()-الجدول3[[#This Row],[اخر تاريخ سداد]])/30 -> 1532.5667 | K25: =SUM('33'!K12:K142) -> 4050 | L25: =SUM('33'!L12:L142) -> 4050 | M25: =الجدول3[[#This Row],[دائن خدمات]]-الجدول3[[#This Row],[مدين خدمات]] -> 0 | O25: =SUM('33'!O12:O143) -> 3000 | P25: =SUM('33'!P12:P143) -> 7600 | Q25: =الجدول3[[#This Row],[دائن مستحقات]]-الجدول3[[#This Row],[مدين مستحقات]] -> -4600
B26: 35 | C26: ='35'!B2 -> إسماعيل إبراهيم | D26: ='35'!B4 -> 2270193812 | E26: ='35'!E6 -> 400 | F26: ='35'!B6 -> 7233 | G26: ='35'!H6 -> 45870 | H26: ='35'!H4 -> أبو عبدالله | I26: =(TODAY()-الجدول3[[#This Row],[اخر تاريخ سداد]])/30 -> 3.5666667 | K26: =SUM('35'!K12:K144) -> 67500 | L26: =SUM('35'!L12:L144) -> 67500 | M26: =الجدول3[[#This Row],[دائن خدمات]]-الجدول3[[#This Row],[مدين خدمات]] -> 0 | O26: =SUM('35'!O12:O145) -> 9600 | P26: =SUM('35'!P12:P145) -> 14400 | Q26: =الجدول3[[#This Row],[دائن مستحقات]]-الجدول3[[#This Row],[مدين مستحقات]] -> -4800 | S26: تحت التواصل
B27: 37 | C27: ='37'!B2 -> سرحان أبو ياسر | D27: ='37'!B4 -> 0 | E27: ='37'!E6 -> 400 | F27: ='37'!B6 -> 6123 | G27: ='37'!H6 -> 45853 | H27: ='37'!H4 -> احمد دقماق | I27: =(TODAY()-الجدول3[[#This Row],[اخر تاريخ سداد]])/30 -> 4.1333333 | K27: =SUM('37'!K12:K146) -> 150 | L27: =SUM('37'!L12:L146) -> 150 | M27: =الجدول3[[#This Row],[دائن خدمات]]-الجدول3[[#This Row],[مدين خدمات]] -> 0 | O27: =SUM('37'!O12:O147) -> 10250 | P27: =SUM('37'!P12:P147) -> 14400 | Q27: =الجدول3[[#This Row],[دائن مستحقات]]-الجدول3[[#This Row],[مدين مستحقات]] -> -4150 | S27: متأخر تحت التواصل
B28: 39 | C28: ='39'!B2 -> عاكف الشهوان | D28: ='39'!B4 -> 2542591397 | E28: ='39'!E6 -> 250 | F28: ='39'!B6 -> - | G28: ='39'!H6 -> 45450 | H28: ='39'!H4 -> رائد عبادي | I28: =(TODAY()-الجدول3[[#This Row],[اخر تاريخ سداد]])/30 -> 17.566667 | K28: =SUM('39'!K12:K148) -> 0 | L28: =SUM('39'!L12:L148) -> 0 | M28: =الجدول3[[#This Row],[دائن خدمات]]-الجدول3[[#This Row],[مدين خدمات]] -> 0 | O28: =SUM('39'!O12:O149) -> 5750 | P28: =SUM('39'!P12:P149) -> 5750 | Q28: =الجدول3[[#This Row],[دائن مستحقات]]-الجدول3[[#This Row],[مدين مستحقات]] -> 0 | S28: تم انهاء العلاقة
B29: 42 | C29: ='42'!B2 -> إبراهيم حمادي | D29: ='42'!B4 -> 2543333583 | E29: ='42'!E6 -> 250 | F29: ='42'!B6 -> - | G29: ='42'!H6 -> 45450 | H29: ='42'!H4 -> رائد عبادي | I29: =(TODAY()-الجدول3[[#This Row],[اخر تاريخ سداد]])/30 -> 17.566667 | K29: =SUM('42'!K12:K151) -> 0 | L29: =SUM('42'!L12:L151) -> 0 | M29: =الجدول3[[#This Row],[دائن خدمات]]-الجدول3[[#This Row],[مدين خدمات]] -> 0 | O29: =SUM('42'!O12:O152) -> 3000 | P29: =SUM('42'!P12:P152) -> 6000 | Q29: =الجدول3[[#This Row],[دائن مستحقات]]-الجدول3[[#This Row],[مدين مستحقات]] -> -3000 | S29: تم انهاء العلاقة
B30: 43 | C30: ='43'!B2 -> رائد عبادي | D30: ='43'!B4 -> 2543333229 | E30: ='43'!E6 -> 250 | F30: ='43'!B6 -> - | G30: ='43'!H6 -> 45450 | H30: ='43'!H4 -> تركيا | I30: =(TODAY()-الجدول3[[#This Row],[اخر تاريخ سداد]])/30 -> 17.566667 | K30: =SUM('43'!K12:K152) -> 0 | L30: =SUM('43'!L12:L152) -> 0 | M30: =الجدول3[[#This Row],[دائن خدمات]]-الجدول3[[#This Row],[مدين خدمات]] -> 0 | O30: =SUM('43'!O12:O153) -> 6000 | P30: =SUM('43'!P12:P153) -> 6000 | Q30: =الجدول3[[#This Row],[دائن مستحقات]]-الجدول3[[#This Row],[مدين مستحقات]] -> 0 | S30: تم انهاء العلاقة
B31: 45 | C31: ='45'!B2 -> محمد صالح | D31: ='45'!B4 -> 2338004068 | E31: ='45'!E6 -> 350 | F31: ='45'!B6 -> 6785 + 1644 | G31: ='45'!H6 -> 45444 | H31: ='45'!H4 -> سمير الخاوي | I31: =(TODAY()-الجدول3[[#This Row],[اخر تاريخ سداد]])/30 -> 17.766667 | K31: =SUM('45'!K12:K154) -> 449300 | L31: =SUM('45'!L12:L154) -> 485000 | M31: =الجدول3[[#This Row],[دائن خدمات]]-الجدول3[[#This Row],[مدين خدمات]] -> -35700 | O31: =SUM('45'!O12:O155) -> 2500 | P31: =SUM('45'!P12:P155) -> 7200 | Q31: =الجدول3[[#This Row],[دائن مستحقات]]-الجدول3[[#This Row],[مدين مستحقات]] -> -4700
B32: 46 | C32: ='46'!B2 -> موسى حسين | D32: ='46'!B4 -> 2305661932 | E32: ='46'!E6 -> 350 | F32: ='46'!B6 -> 7646 | G32: ='46'!H6 -> 45689 | H32: ='46'!H4 -> أبو عبدالله | I32: =(TODAY()-الجدول3[[#This Row],[اخر تاريخ سداد]])/30 -> 9.6 | K32: =SUM('46'!K12:K155) -> 241600 | L32: =SUM('46'!L12:L155) -> 241600 | M32: =الجدول3[[#This Row],[دائن خدمات]]-الجدول3[[#This Row],[مدين خدمات]] -> 0 | O32: =SUM('46'!O12:O156) -> 4750 | P32: =SUM('46'!P12:P156) -> 8400 | Q32: =الجدول3[[#This Row],[دائن مستحقات]]-الجدول3[[#This Row],[مدين مستحقات]] -> -3650
B33: 47 | C33: ='47'!B2 -> عبدالرحمن علي | D33: ='47'!B4 -> 2348671757 | E33: ='47'!E6 -> 300 | F33: ='47'!B6 -> 6800 | G33: ='47'!H6 -> 45658 | H33: ='47'!H4 -> عبدالرحيم حنداد | I33: =(TODAY()-الجدول3[[#This Row],[اخر تاريخ سداد]])/30 -> 10.633333 | K33: =SUM('47'!K12:K156) -> 5450 | L33: =SUM('47'!L12:L156) -> 5450 | M33: =الجدول3[[#This Row],[دائن خدمات]]-الجدول3[[#This Row],[مدين خدمات]] -> 0 | O33: =SUM('47'!O12:O157) -> 2976 | P33: =SUM('47'!P12:P157) -> 7200 | Q33: =الجدول3[[#This Row],[دائن مستحقات]]-الجدول3[[#This Row],[مدين مستحقات]] -> -4224
B34: 48 | C34: ='48'!B2 -> عبدالكريم العامري | D34: ='48'!B4 -> 2377776576 | E34: ='48'!E6 -> 300 | F34: ='48'!B6 -> 2700 | G34: ='48'!H6 -> 45834 | H34: ='48'!H4 -> نفسه | I34: =(TODAY()-الجدول3[[#This Row],[اخر تاريخ سداد]])/30 -> 4.7666667 | K34: =SUM('48'!K12:K157) -> 0 | L34: =SUM('48'!L12:L157) -> 0 | M34: =الجدول3[[#This Row],[دائن خدمات]]-الجدول3[[#This Row],[مدين خدمات]] -> 0 | O34: =SUM('48'!O12:O158) -> 3900 | P34: =SUM('48'!P12:P158) -> 3900 | Q34: =الجدول3[[#This Row],[دائن مستحقات]]-الجدول3[[#This Row],[مدين مستحقات]] -> 0
B35: 50 | C35: ='50'!B2 -> عبدالواحد معصار | D35: ='50'!B4 -> 2572919682 | E35: ='50'!E4 -> 0 | F35: ='50'!B6 -> 7123 | G35: ='50'!H6 -> 45778 | H35: ='50'!H4 -> سمير الخاوي | I35: =(TODAY()-الجدول3[[#This Row],[اخر تاريخ سداد]])/30 -> 6.6333333 | K35: =SUM('50'!K12:K159) -> 145058 | L35: =SUM('50'!L12:L159) -> 145058 | M35: =الجدول3[[#This Row],[دائن خدمات]]-الجدول3[[#This Row],[مدين خدمات]] -> 0 | O35: =SUM('50'!O12:O160) -> 3000 | P35: =SUM('50'!P12:P160) -> 6600 | Q35: =الجدول3[[#This Row],[دائن مستحقات]]-الجدول3[[#This Row],[مدين مستحقات]] -> -3600
B36: 51 | C36: ='51'!B2 -> سمير فارع | D36: ='51'!B4 -> 2183997853 | E36: ='51'!E4 -> 45421 | F36: ='51'!B6 -> 7455 / 7906 | G36: ='51'!H6 -> 45809 | H36: ='51'!H4 -> سمير الخاوي | I36: =(TODAY()-الجدول3[[#This Row],[اخر تاريخ سداد]])/30 -> 5.6 | K36: =SUM('51'!K12:K160) -> 130550 | L36: =SUM('51'!L12:L160) -> 130550 | M36: =الجدول3[[#This Row],[دائن خدمات]]-الجدول3[[#This Row],[مدين خدمات]] -> 0 | O36: =SUM('51'!O12:O161) -> 5000 | P36: =SUM('51'!P12:P161) -> 8400 | Q36: =الجدول3[[#This Row],[دائن مستحقات]]-الجدول3[[#This Row],[مدين مستحقات]] -> -3400 | S36: متأخر في الأقساط
B37: 52 | C37: ='52'!B2 -> جمال جارالله | D37: ='52'!B4 -> 2319609141 | E37: ='52'!E4 -> 45423 | F37: ='52'!B6 -> 2430 | G37: ='52'!H6 -> 45809 | H37: ='52'!H4 -> سمير الخاوي | I37: =(TODAY()-الجدول3[[#This Row],[اخر تاريخ سداد]])/30 -> 5.6 | K37: =SUM('52'!K12:K161) -> 242286 | L37: =SUM('52'!L12:L161) -> 257550 | M37: =الجدول3[[#This Row],[دائن خدمات]]-الجدول3[[#This Row],[مدين خدمات]] -> -15264 | O37: =SUM('52'!O12:O162) -> 0 | P37: =SUM('52'!P12:P162) -> 3600 | Q37: =الجدول3[[#This Row],[دائن مستحقات]]-الجدول3[[#This Row],[مدين مستحقات]] -> -3600 | S37: متأخر في الأقساط
B38: 53 | C38: ='53'!B2 -> ياسر مقبل | D38: ='53'!B4 -> 2265016549 | E38: ='53'!E4 -> 45444 | F38: ='53'!B6 -> 1716 | G38: ='53'!H6 -> 0 | H38: ='53'!H4 -> سمير الخاوي | I38: =(TODAY()-الجدول3[[#This Row],[اخر تاريخ سداد]])/30 -> 1532.5667 | K38: =SUM('53'!K12:K162) -> 325000 | L38: =SUM('53'!L12:L162) -> 325000 | M38: =الجدول3[[#This Row],[دائن خدمات]]-الجدول3[[#This Row],[مدين خدمات]] -> 0 | O38: =SUM('53'!O12:O163) -> 550 | P38: =SUM('53'!P12:P163) -> 3600 | Q38: =الجدول3[[#This Row],[دائن مستحقات]]-الجدول3[[#This Row],[مدين مستحقات]] -> -3050 | S38: متأخر في الأقساط
B39: 54 | C39: ='54'!B2 -> إبراهيم فارع | D39: ='54'!B4 -> 2283202089 | E39: ='54'!E4 -> 0 | F39: ='54'!B6 -> 2070 | G39: ='54'!H6 -> 45597 | H39: ='54'!H4 -> سمير الخاوي | I39: =(TODAY()-الجدول3[[#This Row],[اخر تاريخ سداد]])/30 -> 12.666667 | K39: =SUM('54'!K12:K163) -> 165000 | L39: =SUM('54'!L12:L163) -> 165000 | M39: =الجدول3[[#This Row],[دائن خدمات]]-الجدول3[[#This Row],[مدين خدمات]] -> 0 | O39: =SUM('54'!O12:O164) -> 0 | P39: =SUM('54'!P12:P164) -> 3600 | Q39: =الجدول3[[#This Row],[دائن مستحقات]]-الجدول3[[#This Row],[مدين مستحقات]] -> -3600
B40: 55 | C40: ='55'!B2 -> ياسر الباهلي | D40: ='55'!B4 -> 2304353085 | E40: ='55'!E4 -> 0 | F40: ='55'!B6 -> 1811 | G40: ='55'!H6 -> 45931 | H40: ='55'!H4 -> سمير الخاوي | I40: =(TODAY()-الجدول3[[#This Row],[اخر تاريخ سداد]])/30 -> 1.5333333 | K40: =SUM('55'!K12:K164) -> 230150 | L40: =SUM('55'!L12:L164) -> 230150 | M40: =الجدول3[[#This Row],[دائن خدمات]]-الجدول3[[#This Row],[مدين خدمات]] -> 0 | O40: =SUM('55'!O12:O165) -> 3600 | P40: =SUM('55'!P12:P165) -> 7200 | Q40: =الجدول3[[#This Row],[دائن مستحقات]]-الجدول3[[#This Row],[مدين مستحقات]] -> -3600
B41: 56 | C41: ='56'!B2 -> على الاحرق | D41: ='56'!B4 -> 2195990771 | E41: ='56'!E4 -> 0 | F41: ='56'!B6 -> 1994 | G41: ='56'!H6 -> 45962 | H41: ='56'!H4 -> سمير الخاوي | I41: =(TODAY()-الجدول3[[#This Row],[اخر تاريخ سداد]])/30 -> 0.5 | K41: =SUM('56'!K12:K165) -> 259297 | L41: =SUM('56'!L12:L165) -> 259300 | M41: =الجدول3[[#This Row],[دائن خدمات]]-الجدول3[[#This Row],[مدين خدمات]] -> -3 | O41: =SUM('56'!O12:O166) -> 2100 | P41: =SUM('56'!P12:P166) -> 3600 | Q41: =الجدول3[[#This Row],[دائن مستحقات]]-الجدول3[[#This Row],[مدين مستحقات]] -> -1500
B42: 57 | C42: ='57'!B2 -> احمد مطهر | D42: ='57'!B4 -> 2507980742 | E42: ='57'!E4 -> 0 | F42: ='57'!B6 -> 8116 | G42: ='57'!H6 -> 45536 | H42: ='57'!H4 -> سمير الخاوي | I42: =(TODAY()-الجدول3[[#This Row],[اخر تاريخ سداد]])/30 -> 14.7 | K42: =SUM('57'!K12:K166) -> 95000 | L42: =SUM('57'!L12:L166) -> 95000 | M42: =الجدول3[[#This Row],[دائن خدمات]]-الجدول3[[#This Row],[مدين خدمات]] -> 0 | O42: =SUM('57'!O12:O167) -> 3000 | P42: =SUM('57'!P12:P167) -> 3000 | Q42: =الجدول3[[#This Row],[دائن مستحقات]]-الجدول3[[#This Row],[مدين مستحقات]] -> 0
...

Sheet 1
A2: الاسم | B2: محمد احمد اطرش | D2: الجوال | E2: 0559267482 | G2: طبيعة العمل | H2: سائق شاحنة له | J2: ملاحظات | K2: على الكفاله / لديه شاحنه على اسطول الخليج
A4: الاقامه | B4: 2275610844 | D4: بداية | E4: 44181 | G4: من طرف | H4: ابوبيان
A6: السيارة | D6: شهريا | E6: =3000/12 -> 250 | G6: مسدد الى تاريخ | H6: 44181
A8: كشف السائقين | K8: =SUM(K54:K108) -> 40900 | L8: =SUM(L54:L108) -> 41529 | M8: =K8-L8 -> -629 | O8: =SUM(O12:O108) -> 0 | P8: =SUM(P12:P108) -> 5000 | Q8: =O8-P8 -> -5000
K10: خدمات عامة | O10: مستحقات
A11: م | B11: التاريخ | C11: البيان | K11: دائن | L11: مدين | M11: الرصيد | O11: دائن | P11: مدين | Q11: الرصيد
A12: 1 | B12: 44596 | C12: تامين خالص حسابه | K12: 0 | L12: 0 | M12: =(K12-L12) -> 0 | O12: 0 | P12: 0 | Q12: =O12-P12 -> 0
A13: 2 | B13: 44615 | C13: مبلغ كاش قيمة تغيير عملة مقطوعه | K13: 450 | L13: 0 | M13: =(K13-L13) -> 450 | O13: 0 | P13: 0 | Q13: =O13-P13 -> 0
A14: 3 | B14: 44618 | C14: بالونات من العمري | K14: 0 | L14: 575 | M14: =(K14-L14+M13) -> -125 | O14: 0 | P14: 0 | Q14: =O14-P14+Q13 -> 0
A15: 4 | B15: 44616 | C15: مساعد غمارة | K15: 0 | L15: 330 | M15: =(K15-L15+M14) -> -455 | O15: 0 | P15: 0 | Q15: =O15-P15+Q14 -> 0
A16: 5 | B16: قديم | C16: بطارية براد | K16: 0 | L16: 350 | M16: =(K16-L16+M15) -> -805 | O16: 0 | P16: 0 | Q16: =O16-P16+Q15 -> 0
A17: 6 | B17: قديم | C17: اصلاح ورشة أنور | K17: 0 | L17: 1500 | M17: =(K17-L17+M16) -> -2305 | O17: 0 | P17: 0 | Q17: =O17-P17+Q16 -> 0
A18: 7 | B18: 44625 | C18: سداد مخالفه إشارة | K18: 3000 | L18: 0 | M18: =(K18-L18+M17) -> 695 | O18: 0 | P18: 0 | Q18: =O18-P18+Q17 -> 0
A19: 8 | B19: 44625 | C19: خطاب غرفة تجارية | K19: 0 | L19: 100 | M19: =(K19-L19+M18) -> 595 | O19: 0 | P19: 0 | Q19: =O19-P19+Q18 -> 0
A20: 9 | B20: 44627 | C20: ثلاجة | L20: 850 | M20: =(K20-L20+M19) -> -255 | O20: 0 | P20: 0 | Q20: =O20-P20+Q19 -> 0
A21: 10 | B21: 44636 | C21: حمل من جدة الى دبي | K21: 3000 | L21: 0 | M21: =(K21-L21+M20) -> 2745 | O21: 0 | P21: 0 | Q21: =O21-P21+Q20 -> 0
A22: 11 | C22: حمل من الدمام الى جدة | K22: 1700 | L22: 0 | M22: =(K22-L22+M21) -> 4445 | O22: 0 | P22: 0 | Q22: =O22-P22+Q21 -> 0
A23: 12 | B23: 44690 | C23: حمل من جدة الى الدمام 6108 | K23: 2200 | L23: 0 | M23: =(K23-L23+M22) -> 6645 | O23: 0 | P23: 0 | Q23: =O23-P23+Q22 -> 0
A24: 13 | C24: كاش من ابوبيان و محمد | K24: 0 | L24: 5000 | M24: =(K24-L24+M23) -> 1645 | O24: 0 | P24: 0 | Q24: =O24-P24+Q23 -> 0
A25: 14 | C25: سداد مخالفات على اقامته | K25: 0 | L25: 4600 | M25: =(K25-L25+M24) -> -2955 | O25: 0 | P25: 0 | Q25: =O25-P25+Q24 -> 0
A26: 15 | B26: 44776 | C26: تحويل الى لبنان | K26: 0 | L26: 1500 | M26: =(K26-L26+M25) -> -4455 | O26: 0 | P26: 0 | Q26: =O26-P26+Q25 -> 0
A27: 16 | B27: 44778 | C27: رسوم من 01 / 05 / 1442 الى 01 / 05 / 1443 | K27: 0 | L27: 0 | M27: =(K27-L27+M26) -> -4455 | O27: 0 | P27: =250*12 -> 3000 | Q27: =O27-P27+Q26 -> -3000
A28: 17 | B28: 44778 | C28: رسوم من 01 / 05 / 1443 الى 01 / 01 / 1444 | K28: 0 | L28: 0 | M28: =(K28-L28+M27) -> -4455 | O28: 0 | P28: =250*8 -> 2000 | Q28: =O28-P28+Q27 -> -5000
A29: 18 | C29: تفويض دولي شهر | K29: 0 | L29: 100 | M29: =(K29-L29+M28) -> -4555 | O29: 0 | P29: 0 | Q29: =O29-P29+Q28 -> -5000
A30: 19 | B30: 44842 | C30: تجديد كارت تشغيل 7353 | K30: 0 | L30: 115 | M30: =(K30-L30+M29) -> -4670 | O30: 0 | P30: 0 | Q30: =O30-P30+Q29 -> -5000
A31: 20 | B31: 44880 | C31: تفويض دولي 6 شهور | K31: 0 | L31: 400 | M31: =(K31-L31+M30) -> -5070 | O31: 0 | P31: 0 | Q31: =O31-P31+Q30 -> -5000
A32: 21 | B32: 44883 | C32: تحويل الى عبد القادر اطرش | K32: 0 | L32: 1500 | M32: =(K32-L32+M31) -> -6570 | O32: 0 | P32: 0 | Q32: =O32-P32+Q31 -> -5000
A33: 22 | C33: كارت سائق | L33: 115 | M33: =(K33-L33+M32) -> -6685 | O33: 0 | P33: 0 | Q33: =O33-P33+Q32 -> -5000
A34: 23 | C34: طباعه إقامة | L34: 50 | M34: =(K34-L34+M33) -> -6735 | O34: 0 | P34: 0 | Q34: =O34-P34+Q33 -> -5000
A35: 24 | B35: 44916 | C35: دفعه من مديونية خدمات وقت نقل الكفاله | K35: 2280 | L35: 0 | M35: =(K35-L35+M34) -> -4455 | O35: 0 | P35: 0 | Q35: =O35-P35+Q34 -> -5000
A36: 25 | B36: 44929 | C36: حمل امريكانا من جدة الى الدمام 6710 | K36: 2200 | L36: 0 | M36: =(K36-L36+M35) -> -2255 | O36: 0 | P36: 0 | Q36: =O36-P36+Q35 -> -5000
A37: 26 | B37: 44935 | C37: حملين مناديل من الدمام الى جدة | K37: =1800*2 -> 3600 | L37: 0 | M37: =(K37-L37+M36) -> 1345 | O37: 0 | P37: 0 | Q37: =O37-P37+Q36 -> -5000
A38: 27 | B38: 44941 | C38: حمل امريكانا من جدة الى الدمام 6746 | K38: 2200 | L38: 0 | M38: =(K38-L38+M37) -> 3545 | O38: 0 | P38: 0 | Q38: =O38-P38+Q37 -> -5000
A39: 28 | B39: 44947 | C39: سداد مخالفات على اقامته | K39: 0 | L39: 300 | M39: =(K39-L39+M38) -> 3245 | O39: 0 | P39: 0 | Q39: =O39-P39+Q38 -> -5000
A40: 29 | B40: 44993 | C40: مبلغ محول عن طريق محمد صاحب مهند | L40: 2000 | M40: =(K40-L40+M39) -> 1245 | O40: 0 | P40: 0 | Q40: =O40-P40+Q39 -> -5000
A41: 30 | B41: 45005 | C41: سداد مخالفات على أقامه ابواحمد تخصم من جويل - وقت تمديد التاشيره | K41: 0 | L41: 1800 | M41: =(K41-L41+M40) -> -555 | O41: 0 | P41: 0 | Q41: =O41-P41+Q40 -> -5000
A42: 31 | B42: 45005 | C42: تمديد خروج وعودة شهرين رسوم جوازات + ابشر | K42: 0 | L42: 350 | M42: =(K42-L42+M41) -> -905 | O42: 0 | P42: 0 | Q42: =O42-P42+Q41 -> -5000
A43: 32 | B43: 45017 | C43: شغل السياره حتى 30 / 3 / 2023 | K43: 11210 | L43: 0 | M43: =(K43-L43+M42) -> 10305 | O43: 0 | P43: 0 | Q43: =O43-P43+Q42 -> -5000
A44: 33 | B44: 45025 | C44: مبلغ محول عن طريق محمد صاحب مهند | K44: 0 | L44: 2000 | M44: =(K44-L44+M43) -> 8305 | O44: 0 | P44: 0 | Q44: =O44-P44+Q43 -> -5000
A45: 34 | B45: 45062 | C45: حملين من الدمام الى جدة | K45: =1800*2 -> 3600 | L45: 0 | M45: =(K45-L45+M44) -> 11905 | O45: 0 | P45: 0 | Q45: =O45-P45+Q44 -> -5000
...

Sheet 6
A2: الاسم | B2: أسامة الأشقر | D2: الجوال | E2: 0550125057 | G2: طبيعة العمل | H2: سائق شاحنة له | J2: ملاحظات | K2: على الكفاله / لديه شاحنة على اسطول الخليج
A4: الاقامه | B4: 2270223429 | D4: بداية | E4: 45057 | G4: من طرف | H4: محمد اطرش
A6: السيارة | D6: شهريا | E6: 700 | G6: مسدد الى تاريخ | H6: 45110
A8: كشف السائقين | K8: =SUM(K12:K110) -> 61185 | L8: =SUM(L12:L110) -> 58285 | M8: =K8-L8 -> 2900 | O8: =SUM(O12:O110) -> 12300 | P8: =SUM(P12:P110) -> 27800 | Q8: =O8-P8 -> -15500
K10: خدمات عامة | O10: مستحقات
A11: م | B11: التاريخ | C11: البيان | K11: دائن | L11: مدين | M11: الرصيد | O11: دائن | P11: مدين | Q11: الرصيد
A12: 1 | C12: طباعه استمارة مع مستخدم فعلي | K12: 0 | L12: 200 | M12: =K12-L12 -> -200 | O12: 0 | P12: 0 | Q12: =O12-P12 -> 0
A13: 2 | C13: طباعة إقامة | K13: 200 | L13: 200 | M13: =K13-L13+M12 -> -200 | O13: 0 | P13: 0 | Q13: =O13-P13+Q12 -> 0
A14: 3 | C14: خروج و عودة من الجوازات | K14: 300 | L14: 300 | M14: =K14-L14+M13 -> -200 | O14: 0 | P14: 0 | Q14: =O14-P14+Q13 -> 0
A15: 4 | C15: كارت عمل 3 شهور | K15: 0 | L15: 2425 | M15: =K15-L15+M14 -> -2625 | O15: 0 | P15: 0 | Q15: =O15-P15+Q14 -> 0 | Z15: الصافي | AA15: =AA16-AB16 -> 82150
A16: 5 | C16: تامين طبي | K16: 0 | L16: 1700 | M16: =K16-L16+M15 -> -4325 | O16: 0 | P16: 0 | Q16: =O16-P16+Q15 -> 0 | Z16: الإجمالي | AA16: =SUM(AA18:AA31) -> 153850 | AB16: =SUM(AB18:AB31) -> 71700
A17: 6 | C17: رسوم جوازات 3 شهور | K17: 0 | L17: 163 | M17: =K17-L17+M16 -> -4488 | O17: 0 | P17: 0 | Q17: =O17-P17+Q16 -> 0 | X17: م | Y17: الدفع | Z17: البيان | AA17: له | AB17: عليه
A18: 7 | B18: 44739 | C18: رسوم خروج وعودة متعدده 4 شهور + اتعاب المكتب + نقل معلومات | K18: 0 | L18: =200+250+500 -> 950 | M18: =K18-L18+M17 -> -5438 | O18: 0 | P18: 0 | Q18: =O18-P18+Q17 -> 0 | X18: 1 | Y18: مدفوع من ابوحذيفة | Z18: بيع البراد | AA18: 45000 | AB18: 0
A19: 8 | B19: 44739 | C19: دفعة من مديونية سابقة | K19: 5460 | L19: 0 | M19: =K19-L19+M18 -> 22 | O19: 0 | P19: 0 | Q19: =O19-P19+Q18 -> 0 | X19: 2 | Z19: بيع الراس | AA19: 55000 | AB19: 0
A20: 9 | B20: 44742 | C20: قيمة استيكر معلومات ترخيص | K20: 0 | L20: 60 | M20: =K20-L20+M19 -> -38 | O20: 0 | P20: 0 | Q20: =O20-P20+Q19 -> 0 | X20: 3 | Z20: كاش لابوبيان | AA20: 25000 | AB20: 0
A21: 10 | C21: رسوم 8 اشهر من 01 / 07 / 1443 الى 01 / 03 / 1444 | K21: 0 | L21: -38 | M21: =K21-L21+M20 -> 0 | O21: 0 | P21: =700*8 -> 5600 | Q21: =O21-P21+Q20 -> -5600 | X21: 4 | Y21: مصروف من أبو حذيفة | Z21: مبلغ مسلم الى أبو حسن | AA21: 0 | AB21: 20000
A22: 11 | C22: تجديد 6 اشهر ( كارت عمل 4850 + جوازات 325 ) | K22: =4850+325 -> 5175 | L22: 5175 | M22: =K22-L22+M21 -> 0 | O22: 0 | P22: 0 | Q22: =O22-P22+Q21 -> -5600 | X22: 5 | Z22: تجديد أقامه | AA22: 0 | AB22: =9700+1650 -> 11350
A23: 12 | B23: 44850 | C23: سداد مخالفه وقوف / تم السداد في 16 / 10 | K23: 100 | L23: 100 | M23: =K23-L23+M22 -> 0 | O23: 0 | P23: 0 | Q23: =O23-P23+Q22 -> -5600 | X23: 6 | Z23: خ و عودة | AA23: 0 | AB23: 200
A24: 13 | B24: 44850 | C24: سداد تمديد خ و عودة شهر / تم السداد في 16 / 10 | K24: 200 | L24: 200 | M24: =K24-L24+M23 -> 0 | O24: 0 | P24: 0 | Q24: =O24-P24+Q23 -> -5600 | X24: 7 | Z24: تحويل الى الأردن | AA24: 0 | AB24: 5000
A25: 14 | B25: 44850 | C25: خروج وعودة متعدد 4 شهور من الجوازات | K25: 700 | L25: 700 | M25: =K25-L25+M24 -> 0 | O25: 0 | P25: 0 | Q25: =O25-P25+Q24 -> -5600 | X25: 8 | Z25: تجديد بطاقة سائق | AA25: 0 | AB25: 150
A26: 15 | B26: 44850 | C26: دفعه من رسوم 8 اشهر من 01 / 07 / 1443 الى 01 / 03 / 1444 | K26: 0 | L26: 0 | M26: =K26-L26+M25 -> 0 | O26: 2500 | P26: 0 | Q26: =O26-P26+Q25 -> -3100 | X26: 9 | Z26: ايجار السكن فالحله | AA26: 0 | AB26: 6000 | AD26: 125
A27: 16 | B27: 44850 | C27: كارت تشغيل | K27: 150 | L27: 150 | M27: =K27-L27+M26 -> 0 | O27: 0 | P27: 0 | Q27: =O27-P27+Q26 -> -3100 | X27: 10 | Z27: كاش وقت السفر لسوريا | AA27: 0 | AB27: 10000 | AD27: 30
A28: 17 | C28: تحويل قيمة تجديد استمارة سير / | K28: 1200 | L28: 0 | M28: =K28-L28+M27 -> 1200 | O28: 0 | P28: 0 | Q28: =O28-P28+Q27 -> -3100 | X28: 11 | Z28: تفعيل الزياره العائلية | AA28: 0 | AB28: 6500
A29: 18 | C29: استرجاع رسوم باقي التجديد | K29: 500 | L29: 0 | M29: =K29-L29+M28 -> 1700 | O29: 0 | P29: 0 | Q29: =O29-P29+Q28 -> -3100 | X29: 12 | Z29: زيارة مهذب | AA29: 0 | AB29: 1500
A30: 19 | B30: 44851 | C30: تجديد رخصة سير | K30: 0 | L30: 1500 | M30: =K30-L30+M29 -> 200 | O30: 0 | P30: 0 | Q30: =O30-P30+Q29 -> -3100 | X30: 13 | Z30: تحويلات لسوريا ولبنان | AA30: 0 | AB30: =5000+2000+2000+2000 -> 11000
A31: 20 | B31: 44861 | C31: تقرير مقيم | K31: 0 | L31: 50 | M31: =K31-L31+M30 -> 150 | O31: 0 | P31: 0 | Q31: =O31-P31+Q30 -> -3100 | X31: 14 | Y31: تصفية الراس | Z31: الراس الخضراء ( قيمة 188 - بيع 230 - ربح 42 ) ( خصم قيمة كفرين ويستليك على أبو حذيفة ) ( خصم كفاله 29 شهر * 350 = 10150 | AA31: =42000-3000-10150 -> 28850 | AB31: 0
A32: 21 | B32: 44879 | C32: تأشيرة زياره | K32: 0 | L32: 200 | M32: =K32-L32+M31 -> -50 | O32: 0 | P32: 0 | Q32: =O32-P32+Q31 -> -3100 | X32: 15
A33: 22 | B33: 44880 | C33: قيمة ايجار حمل بحرين بوليصة 6415 تم خصمها عليه بالكامل | K33: 50 | L33: 0 | M33: =K33-L33+M32 -> 0 | O33: 3650 | P33: 0 | Q33: =O33-P33+Q32 -> 550 | X33: 16
A34: 23 | B34: 44880 | C34: اصدار بطاقه سائق | K34: 0 | L34: 150 | M34: =K34-L34+M33 -> -150 | O34: 0 | P34: 0 | Q34: =O34-P34+Q33 -> 550 | X34: 17
A35: 24 | B35: 44880 | C35: تحويل على 110 لاقفال الحساب الى تاريخه | K35: 150 | L35: 0 | M35: =K35-L35+M34 -> 0 | O35: 150 | P35: 0 | Q35: =O35-P35+Q34 -> 700 | X35: 18
A36: 26 | B36: 44927 | C36: رسوم 6 اشهر من 01 / 03 / 1444 الى 01 / 09 / 1444 | K36: 0 | L36: 0 | M36: =K36-L36+M35 -> 0 | O36: 0 | P36: =700*6 -> 4200 | Q36: =O36-P36+Q35 -> -3500 | X36: 19
A37: 27 | B37: 44957 | C37: دفعه من مديونيه خدمات | K37: 800 | L37: 0 | M37: =K37-L37+M36 -> 800 | O37: 0 | P37: 0 | Q37: =O37-P37+Q36 -> -3500 | X37: 20
A38: 28 | B38: 44957 | C38: سداد رسوم خ وعودة شهرين | K38: 0 | L38: 200 | M38: =K38-L38+M37 -> 600 | O38: 0 | P38: 0 | Q38: =O38-P38+Q37 -> -3500 | X38: 21
A39: 29 | B39: 44987 | C39: دفعه من مديونية مستحقات 5 شهور الى 1 / 9 / 1444 | K39: 0 | L39: 0 | M39: =K39-L39+M38 -> 600 | O39: 3500 | P39: 0 | Q39: =O39-P39+Q38 -> 0 | X39: 22
A40: 30 | B40: 45080 | C40: رسوم 12 شهر من 1 / 09 / 1444 الى 1 / 09 / 1445 | K40: 0 | L40: 0 | M40: =K40-L40+M39 -> 600 | O40: 0 | P40: =700*12 -> 8400 | Q40: =O40-P40+Q39 -> -8400
A41: 31 | C41: كاش 1900 + تحويل 600 خدمات الى مستحقات الى 15 / 12 / 1444 | K41: 0 | L41: 0 | M41: 0 | O41: =1900+600 -> 2500 | P41: 0 | Q41: =O41-P41+Q40 -> -5900
A42: 32 | B42: 45294 | C42: تغيير منهة | K42: 1200 | L42: 1200 | M42: =K42-L42+M41 -> 0 | O42: 0 | P42: 0 | Q42: =O42-P42+Q41 -> -5900
A43: 33 | B43: 45689 | C43: رسوم 12 شهر من 1 / 09 / 1445 الى 1 / 09 / 1446 | K43: 0 | L43: 0 | M43: =K43-L43+M42 -> 0 | O43: 0 | P43: =12*400 -> 4800 | Q43: =O43-P43+Q42 -> -10700
A44: 34 | B44: 45809 | C44: رسوم 12 شهر من 1 / 09 / 1446 الى 1 / 09 / 1447 | K44: 0 | L44: 0 | M44: =K44-L44+M43 -> 0 | O44: 0 | P44: =12*400 -> 4800 | Q44: =O44-P44+Q43 -> -15500
A45: 35 | B45: 45809 | C45: مبلغ مسلم الى أبو حسن | K45: 0 | L45: 20000 | M45: =K45-L45+M44 -> -20000 | O45: 0 | P45: 0 | Q45: =O45-P45+Q44 -> -15500
...

Sheet 7
A2: الاسم | B2: عبدالرزاق أحمد | D2: الجوال | E2: 0531842166 | G2: طبيعة العمل | H2: سائق شاحنة له | J2: ملاحظات | K2: على الكفاله / لديه شاحنة على اسطول الخليج
A4: الاقامه | B4: 2244421182 | D4: بداية | E4: 44740 | G4: من طرف | H4: محمد اطرش
A6: السيارة | B6: 6972 | D6: شهريا | E6: 700 | G6: مسدد الى تاريخ | H6: 45809
A8: كشف السائقين | K8: =SUM(K12:K111) -> 43147 | L8: =SUM(L12:L111) -> 43097 | M8: =K8-L8 -> 50 | O8: =SUM(O12:O111) -> 28900 | P8: =SUM(P12:P111) -> 33600 | Q8: =O8-P8 -> -4700
Y9: =Y11-Z11 -> -12170
K10: خدمات عامة | O10: مستحقات
A11: م | B11: التاريخ | C11: البيان | K11: دائن | L11: مدين | M11: الرصيد | O11: دائن | P11: مدين | Q11: الرصيد | Y11: =SUM(Y13:Y41) -> 62825 | Z11: =SUM(Z13:Z41) -> 74995
A12: 1 | B12: 44562 | C12: دفعة 1 تحت حساب النقل | K12: 7600 | L12: 0 | M12: =K12-L12 -> 7600 | O12: 0 | P12: 0 | Q12: =O12-P12 -> 0 | W12: م | X12: البيان | Y12: له | Z12: عليه
A13: 2 | B13: 44566 | C13: سداد مخالفات | K13: 0 | L13: 1950 | M13: =K13-L13+M12 -> 5650 | O13: 0 | P13: 0 | Q13: =O13-P13+Q12 -> 0 | W13: 1 | X13: كاش دولار الى ابوبيان ( 14000 ) | Y13: =14000*3.75 -> 52500 | Z13: 0
A14: 3 | B14: 44570 | C14: تامين السيارة | K14: 0 | L14: 2400 | M14: =K14-L14+M13 -> 3250 | O14: 0 | P14: 0 | Q14: =O14-P14+Q13 -> 0 | W14: 2 | X14: كاش الى ابوبيان | Y14: 10325 | Z14: 0
A15: 4 | B15: 44570 | C15: رسوم نقل | K15: 0 | L15: 300 | M15: =K15-L15+M14 -> 2950 | O15: 0 | P15: 0 | Q15: =O15-P15+Q14 -> 0 | W15: 3 | X15: مبلغ مسترد كاش الى عبدالرزاق | Y15: 0 | Z15: 10825
A16: 5 | B16: 44570 | C16: مبايعة | K16: 0 | L16: 500 | M16: =K16-L16+M15 -> 2450 | O16: 0 | P16: 0 | Q16: =O16-P16+Q15 -> 0 | W16: 4 | X16: مبلغ مستحق الى وسيم | Y16: 0 | Z16: 64170
A17: 6 | B17: 44570 | C17: بدل فاقد | K17: 0 | L17: 200 | M17: =K17-L17+M16 -> 2250 | O17: 0 | P17: 0 | Q17: =O17-P17+Q16 -> 0
A18: 7 | B18: 44570 | C18: اتعاب معقب | K18: 0 | L18: 300 | M18: =K18-L18+M17 -> 1950 | O18: 0 | P18: 0 | Q18: =O18-P18+Q17 -> 0
A19: 8 | B19: 44570 | C19: كارت ميزان | K19: 0 | L19: 115 | M19: =K19-L19+M18 -> 1835 | O19: 0 | P19: 0 | Q19: =O19-P19+Q18 -> 0
A20: 9 | B20: 44574 | C20: دفعة 2 تحت حساب النقل | K20: 3000 | L20: 0 | M20: =K20-L20+M19 -> 4835 | O20: 0 | P20: 0 | Q20: =O20-P20+Q19 -> 0
A21: 10 | B21: 44585 | C21: سداد رسوم نقل كفالة / العامل مسدد من قبل 600 | K21: 0 | L21: 5400 | M21: =K21-L21+M20 -> -565 | O21: 0 | P21: 0 | Q21: =O21-P21+Q20 -> 0
A22: 11 | B22: 44586 | C22: دفعة 3 تحت حساب النقل | K22: 3700 | L22: 0 | M22: =K22-L22+M21 -> 3135 | O22: 0 | P22: 0 | Q22: =O22-P22+Q21 -> 0
A23: 12 | B23: 44587 | C23: سداد رسوم خروج وعودة متعددة 5 أشهر | K23: 0 | L23: 900 | M23: =K23-L23+M22 -> 2235 | O23: 0 | P23: 0 | Q23: =O23-P23+Q22 -> 0
A24: 13 | B24: 44592 | C24: تحويل الى معقب لعمل تفويض دولي | K24: 0 | L24: 500 | M24: =K24-L24+M23 -> 1735 | O24: 0 | P24: 0 | Q24: =O24-P24+Q23 -> 0
A25: 14 | B25: 44592 | C25: طباعه إقامة | K25: 0 | L25: 100 | M25: =K25-L25+M24 -> 1635 | O25: 0 | P25: 0 | Q25: =O25-P25+Q24 -> 0
A26: 15 | B26: 44666 | C26: كارت عمل | K26: 0 | L26: 9700 | M26: =K26-L26+M25 -> -8065 | O26: 0 | P26: 0 | Q26: =O26-P26+Q25 -> 0
A27: 16 | B27: 44666 | C27: رسوم جوازات | K27: 0 | L27: 650 | M27: =K27-L27+M26 -> -8715 | O27: 0 | P27: 0 | Q27: =O27-P27+Q26 -> 0
A28: 17 | B28: 44666 | C28: خروج وعودة متعدده سنه | K28: 0 | L28: 2300 | M28: =K28-L28+M27 -> -11015 | O28: 0 | P28: 0 | Q28: =O28-P28+Q27 -> 0
... A30: 19 | B30: 44666 | C30: تامين طبي | K30: 0 | L30: 1812 | M30: =K30-L30+M29 -> -1812 | O30: 0 | P30: 0 | Q30: =O30-P30+Q29 -> 0
A31: 20 | B31: 44666 | C31: رسوم مؤسسة 12 شهور من 01 / 07 / 1443 الى 01 / 07 / 1444 | K31: 0 | L31: 0 | M31: =K31-L31+M30 -> -1812 | O31: 0 | P31: =700*12 -> 8400 | Q31: =O31-P31+Q30 -> -8400
A32: 21 | B32: 44745 | C32: تفويض دولي 6 شهور الى تاريخ 3 / 6 / 1444 | K32: 0 | L32: 400 | M32: =K32-L32+M31 -> -2212 | O32: 0 | P32: 0 | Q32: =O32-P32+Q31 -> -8400
A33: 22 | B33: 44745 | C33: سداد غارمة تأخير في المينا | K33: 0 | L33: 400 | M33: =K33-L33+M32 -> -2612 | O33: 0 | P33: 0 | Q33: =O33-P33+Q32 -> -8400
A34: 23 | C34: اصلاح السياره عند أنور | K34: 0 | L34: 200 | M34: =K34-L34+M33 -> -2812 | O34: 0 | P34: 0 | Q34: =O34-P34+Q33 -> -8400
A35: 24 | B35: 44854 | C35: سداد رسوم تجديد رخصة سير | K35: 0 | L35: 900 | M35: =K35-L35+M34 -> -3712 | O35: 0 | P35: 0 | Q35: =O35-P35+Q34 -> -8400
A36: 25 | B36: 44854 | C36: دفعه 5000 من مديونيه خدمات ومستحقات الى 1 / 9 / 1443 | K36: 3700 | L36: 0 | M36: =K36-L36+M35 -> -12 | O36: 1300 | P36: 0 | Q36: =O36-P36+Q35 -> -7100
A37: 26 | B37: 44902 | C37: اصدار كارت سائق | K37: 0 | L37: 150 | M37: =K37-L37+M36 -> -162 | O37: 0 | P37: 0 | Q37: =O37-P37+Q36 -> -7100
A38: 27 | B38: 44920 | C38: تجديد كارت التشغيل | K38: 0 | L38: 150 | M38: =K38-L38+M37 -> -312 | O38: 0 | P38: 0 | Q38: =O38-P38+Q37 -> -7100
A39: 28 | B39: 44920 | C39: سداد مخالفات على اقامته | K39: 0 | L39: 750 | M39: =K39-L39+M38 -> -1062 | O39: 0 | P39: 0 | Q39: =O39-P39+Q38 -> -7100
A40: 29 | C40: دفعه من المستحقات والخدمات مسلمه كاش الى محمد سلامه بجدة | K40: 1050 | L40: 0 | M40: =K40-L40+M39 -> -12 | O40: =5450-1050 -> 4400 | P40: 0 | Q40: =O40-P40+Q39 -> -2700
A41: 30 | B41: 44926 | C41: دفعه من مستحقات سداد الى 1 / 7 / 1444 | K41: 0 | L41: 0 | M41: =K41-L41+M40 -> -12 | O41: 2700 | P41: 0 | Q41: =O41-P41+Q40 -> 0
A42: 31 | C42: تامين سياره | K42: =1360+400+800 -> 2560 | L42: 2550 | M42: =K42-L42+M41 -> -2 | O42: 0 | P42: 0 | Q42: =O42-P42+Q41 -> 0
A43: 32 | B43: 44931 | C43: جهاز تتبع | K43: 0 | L43: 1150 | M43: =K43-L43+M42 -> -1152 | O43: 0 | P43: 0 | Q43: =O43-P43+Q42 -> 0
A44: 33 | B44: 44957 | C44: مبلغ مسترد من السعودة لتتبع المركبات | K44: 352 | L44: 0 | M44: =K44-L44+M43 -> -800 | O44: 0 | P44: 0 | Q44: =O44-P44+Q43 -> 0
A45: 34 | B45: 44958 | C45: مستحقات 12 شهر من 01 / 07 / 1444 الى 01 / 07 / 1445 | K45: 0 | L45: 0 | M45: =K45-L45+M44 -> -800 | O45: 0 | P45: =700*12 -> 8400 | Q45: =O45-P45+Q44 -> -8400
...

Sheet 8
A2: الاسم | B2: اديب محمد | D2: الجوال | E2: 0500822670 | G2: طبيعة العمل | H2: سائق شاحنة له | J2: ملاحظات | K2: على الكفاله / لديه شاحنة على اسطول الخليج
A4: الاقامه | B4: 2305927978 | D4: بداية | E4: 44765 | G4: من طرف | H4: محمد اطرش
A6: السيارة | B6: 1527 | D6: شهريا | E6: 700 | G6: مسدد الى تاريخ | H6: 45839
A8: كشف السائقين | K8: =SUM(K12:K110) -> 57553 | L8: =SUM(L12:L110) -> 56296 | M8: =K8-L8 -> 1257 | O8: =SUM(O12:O110) -> 30850 | P8: =SUM(P12:P110) -> 33600 | Q8: =O8-P8 -> -2750 | X8: الباقي على اديب | Z8: =Z10-AA10 -> 0
K10: خدمات عامة | O10: مستحقات | X10: الإجمالي | Z10: =SUM(Z12:Z36) -> 228486 | AA10: =SUM(AA12:AA36) -> 228486
A11: م | B11: التاريخ | C11: البيان | K11: دائن | L11: مدين | M11: الرصيد | O11: دائن | P11: مدين | Q11: الرصيد
A12: 1 | B12: 44562 | C12: دفعة 1 تحت حساب النقل | K12: 6100 | L12: 0 | M12: =K12-L12 -> 6100 | O12: 0 | P12: 0 | Q12: =O12-P12 -> 0 | X12: 1 | Y12: قيمة السياره | Z12: 220000
A13: 2 | B13: 44566 | C13: سداد مخالفات مرور | K13: 0 | L13: 1300 | M13: =K13-L13+M12 -> 4800 | O13: 0 | P13: 0 | Q13: =O13-P13+Q12 -> 0 | X13: 2 | Y13: تامين السياره | Z13: 2450
A14: 3 | B14: 44570 | C14: تامين السيارة | K14: 0 | L14: 2400 | M14: =K14-L14+M13 -> 2400 | O14: 0 | P14: 0 | Q14: =O14-P14+Q13 -> 0 | X14: 3 | Y14: فحص دوري اول مره | Z14: 269
A15: 4 | B15: 44570 | C15: رسوم نقل | K15: 0 | L15: 300 | M15: =K15-L15+M14 -> 2100 | O15: 0 | P15: 0 | Q15: =O15-P15+Q14 -> 0 | X15: 4 | Y15: فحص دوري ثاني مره | Z15: 67
A16: 5 | B16: 44570 | C16: مبايعة | K16: 0 | L16: 500 | M16: =K16-L16+M15 -> 1600 | O16: 0 | P16: 0 | Q16: =O16-P16+Q15 -> 0 | X16: 5 | Y16: صاجات حواجز | Z16: 200
A17: 6 | B17: 44570 | C17: بدل فاقد | K17: 0 | L17: 200 | M17: =K17-L17+M16 -> 1400 | O17: 0 | P17: 0 | Q17: =O17-P17+Q16 -> 0 | X17: 6 | Y17: استيكر فحص | Z17: 150
A18: 7 | B18: 44570 | C18: اتعاب معقب | K18: 0 | L18: 300 | M18: =K18-L18+M17 -> 1100 | O18: 0 | P18: 0 | Q18: =O18-P18+Q17 -> 0 | X18: 7 | Y18: اصدار استماره ولوحات | Z18: 1500
A19: 8 | B19: 44570 | C19: كارت ميزان | K19: 0 | L19: 115 | M19: =K19-L19+M18 -> 985 | O19: 0 | P19: 0 | Q19: =O19-P19+Q18 -> 0 | X19: 8 | Y19: تعقيب | Z19: 300
A20: 9 | B20: 44584 | C20: دفعة 2 تحت حساب النقل | K20: 3800 | L20: 0 | M20: =K20-L20+M19 -> 4785 | O20: 0 | P20: 0 | Q20: =O20-P20+Q19 -> 0 | X20: 9 | Y20: جهاز تتبع | Z20: 1100
A21: 10 | B21: 44585 | C21: سداد رسوم نقل كفالة / العامل مسدد من قبل 400 | K21: 0 | L21: 3600 | M21: =K21-L21+M20 -> 1185 | O21: 0 | P21: 0 | Q21: =O21-P21+Q20 -> 0 | X21: 10 | Y21: تلميع | Z21: 450
A22: 11 | B22: 44587 | C22: سداد رسوم خروج وعودة متعددة 5 أشهر | K22: 0 | L22: 900 | M22: =K22-L22+M21 -> 285 | O22: 0 | P22: 0 | Q22: =O22-P22+Q21 -> 0 | X22: 11 | Y22: باقي حساب حفر الباطن | Z22: 300
A23: 12 | B23: 44592 | C23: تحويل الى معقب لعمل تفويض دولي | K23: 0 | L23: 500 | M23: =K23-L23+M22 -> -215 | O23: 0 | P23: 0 | Q23: =O23-P23+Q22 -> 0 | X23: 12 | Y23: كارت تشغيل | Z23: 200
A24: 13 | B24: 44592 | C24: طباعه إقامة | K24: 0 | L24: 100 | M24: =K24-L24+M23 -> -315 | O24: 0 | P24: 0 | Q24: =O24-P24+Q23 -> 0 | X24: 13 | Y24: تغيير زيت | Z24: 1000
A25: 14 | B25: 44598 | C25: قيمة حادث مروري | K25: 6653 | L25: 0 | M25: =K25-L25+M24 -> 6338 | O25: 0 | P25: 0 | Q25: =O25-P25+Q24 -> 0 | X25: 14 | Z25: 300
A26: 15 | B26: 44648 | C26: تحويل الى حساب محمد الشيخو | K26: 0 | L26: 2000 | M26: =K26-L26+M25 -> 4338 | O26: 0 | P26: 0 | Q26: =O26-P26+Q25 -> 0 | X26: 15 | Y26: جاسم | Z26: 200
A27: 16 | B27: 44666 | C27: خروج وعودة من رصيد على اقامته | K27: 0 | L27: 0 | M27: =K27-L27+M26 -> 4338 | O27: 0 | P27: 0 | Q27: =O27-P27+Q26 -> 0 | X27: 16 | Y27: دفعه 1 من قيمة السياره | AA27: 180000
A28: 17 | B28: 44712 | C28: تحويل قيمة حمل الى اديب / تم اضافته للرسوم | K28: 400 | L28: 0 | M28: =K28-L28+M27 -> 4738 | O28: 1200 | P28: 0 | Q28: =O28-P28+Q27 -> 1200 | X28: 17 | Y28: دفعه 2 من قيمة السياره | AA28: 1700
A29: 18 | B29: 44713 | C29: كاش من اديب / تم اضافته للرسوم | K29: 0 | L29: 0 | M29: =K29-L29+M28 -> 4738 | O29: 1000 | P29: 0 | Q29: =O29-P29+Q28 -> 2200 | X29: 18 | Y29: دفعه 3 من قيمة السياره | AA29: 2690
A30: 19 | B30: 44713 | C30: رسوم مؤسسة 12 شهرمن 01 / 07 / 1443 الى 01 / 07 / 1444 | K30: 0 | L30: 0 | M30: =K30-L30+M29 -> 4738 | O30: 0 | P30: =12*700 -> 8400 | Q30: =O30-P30+Q29 -> -6200 | X30: 19 | Y30: دفعه 4 من قيمة السياره ت 27 / 06 / 2023 | AA30: 10000
A31: 20 | B31: 44717 | C31: كارت عمل 3 شهور | K31: 0 | L31: 2425 | M31: =K31-L31+M30 -> 2313 | O31: 0 | P31: 0 | Q31: =O31-P31+Q30 -> -6200 | X31: 20 | Y31: دفعه 5 من قيمة السياره ت 14 / 01 / 2024 | AA31: 13000
A32: 21 | B32: 44717 | C32: تامين طبي | K32: 0 | L32: 1700 | M32: =K32-L32+M31 -> 613 | O32: 0 | P32: 0 | Q32: =O32-P32+Q31 -> -6200 | X32: 21 | Y32: دفعه 6 من قيمة السياره ت 25 / 03 / 2024 | AA32: 2000
A33: 22 | B33: 44717 | C33: رسوم جوازات 3 شهور | K33: 0 | L33: 163 | M33: =K33-L33+M32 -> 450 | O33: 0 | P33: 0 | Q33: =O33-P33+Q32 -> -6200 | X33: 22 | Y33: دفعه 6 من قيمة السياره مقابله على الطريق مع ابوبيان وعائلته | AA33: 7000
A34: 23 | B34: 44717 | C34: رسوم تاشيره متعدده 3 شهور | K34: 0 | L34: 500 | M34: =K34-L34+M33 -> -50 | O34: 0 | P34: 0 | Q34: =O34-P34+Q33 -> -6200 | X34: 23 | Y34: تحويل على راجحي جاسم 25 / 6 / 2025 | AA34: 2000
A35: 24 | B35: 44758 | C35: تفويض دولي الى 7 / 2 / 1444 | K35: 0 | L35: 100 | M35: =K35-L35+M34 -> -150 | O35: 0 | P35: 0 | Q35: =O35-P35+Q34 -> -6200 | X35: 24 | Y35: كاش لابوبيان عن طريق وسيم 28 / 6 / 2025 | AA35: 10000
A36: 25 | B36: 44763 | C36: شراء مضخة ديزل الى سواق هندي تبعنا | K36: 150 | L36: 0 | M36: =K36-L36+M35 -> 0 | O36: 0 | P36: 0 | Q36: =O36-P36+Q35 -> -6200 | X36: 25 | Y36: خصم من رصيد الخدمات | AA36: 96
A37: 26 | B37: 44763 | C37: دفعه من الحساب - تم اضافتها للرسوم | K37: 0 | L37: 0 | M37: =K37-L37+M36 -> 0 | O37: 2000 | P37: 0 | Q37: =O37-P37+Q36 -> -4200
A38: 28 | B38: 44805 | C38: دفعه من تجديد الاقامه | K38: 10000 | L38: 0 | M38: =K38-L38+M37 -> 10000 | O38: 0 | P38: 0 | Q38: =O38-P38+Q37 -> -4200 | X38: 22 | Y38: جهاز تبريد وسيم | Z38: 22000
A39: 29 | B39: 44805 | C39: كارت عمل 12 شهر | K39: 0 | L39: 9700 | M39: =K39-L39+M38 -> 300 | O39: 0 | P39: 0 | Q39: =O39-P39+Q38 -> -4200 | X39: 23 | Y39: دفعه من جهاز التبريد مسلمه في دبي | AA39: 10000
A40: 30 | B40: 44805 | C40: رسوم جوازات 12 شهور | K40: 0 | L40: 650 | M40: =K40-L40+M39 -> -350 | O40: 0 | P40: 0 | Q40: =O40-P40+Q39 -> -4200
A41: 31 | B41: 44805 | C41: رسوم خروج وعودة 12 شهر | K41: 0 | L41: 2300 | M41: =K41-L41+M40 -> -2650 | O41: 0 | P41: 0 | Q41: =O41-P41+Q40 -> -4200
A42: 32 | B42: 44805 | C42: تفويض دولي 6 شهر | K42: 0 | L42: 0 | M42: =K42-L42+M41 -> -2650 | O42: 0 | P42: 0 | Q42: =O42-P42+Q41 -> -4200
A43: 33 | B43: 44902 | C43: دفعه من مديونية خدمات ومستحقات 01 / 04 / 1444 | K43: 2800 | L43: 0 | M43: =K43-L43+M42 -> 150 | O43: 2200 | P43: 0 | Q43: =O43-P43+Q42 -> -2000
A44: 34 | B44: 44928 | C44: اصدار كارت سائق | K44: 0 | L44: 150 | M44: =K44-L44+M43 -> 0 | O44: 0 | P44: 0 | Q44: =O44-P44+Q43 -> -2000
A45: 35 | B45: 44930 | C45: تجديد كارت ميزان | K45: 0 | L45: 230 | M45: =K45-L45+M44 -> -230 | O45: 0 | P45: 0 | Q45: =O45-P45+Q44 -> -2000
...

Sheet 9
A2: الاسم | B2: عصام الريح | D2: الجوال | E2: 0509458267 | G2: طبيعة العمل | H2: يدير عمل شاحنات خاص به | J2: ملاحظات | K2: ليس على الكفاله / لديه سيارتين على اسطول الخليج (5540-3656-9155) / تواصل في 30 / 1 / 2025
A4: الاقامه | B4: 2133835989 | D4: بداية | E4: 44712 | G4: من طرف | H4: ابوبيان
A6: السيارة | B6: 3656 - 4383 | D6: شهريا | E6: 1000 | G6: مسدد الى تاريخ | H6: 44712
A8: كشف السائقين | K8: =SUM(K12:K111) -> 22300 | L8: =SUM(L12:L111) -> 535 | M8: =K8-L8 -> 21765 | O8: =SUM(O12:O111) -> 13100 | P8: =SUM(P12:P111) -> 39000 | Q8: =O8-P8 -> -25900
K10: خدمات عامة | O10: مستحقات
A11: م | B11: التاريخ | C11: البيان | K11: دائن | L11: مدين | M11: الرصيد | O11: دائن | P11: مدين | Q11: الرصيد
A12: 1 | B12: 44571 | C12: مبلغ تحت الحساب | K12: 16700 | L12: 0 | M12: =K12-L12 -> 16700 | O12: 0 | P12: 0 | Q12: =O12-P12 -> 0
A13: 2 | B13: 44571 | C13: تصديق خطاب غرفة تجارية | K13: 0 | L13: 35 | M13: =K13-L13+M12 -> 16665 | O13: 0 | P13: 0 | Q13: =O13-P13+Q12 -> 0
A14: 3 | B14: 44572 | C14: دفعه 2 تحت الحساب | K14: 2100 | L14: 0 | M14: =K14-L14+M13 -> 18765 | O14: 0 | P14: 0 | Q14: =O14-P14+Q13 -> 0
A15: 4 | B15: 44640 | C15: مخالفه تنظيم سير رقم 831 + حزام رقم 1738 | K15: 0 | L15: 300 | M15: =K15-L15+M14 -> 18465 | O15: 0 | P15: 0 | Q15: =O15-P15+Q14 -> 0
A16: 5 | B16: 44641 | C16: معامله السيارات | K16: 0 | L16: 0 | M16: =K16-L16+M15 -> 18465 | O16: 0 | P16: 0 | Q16: =O16-P16+Q15 -> 0
A17: 6 | B17: 44710 | C17: سداد مخالفات شهر مارس | K17: 300 | L17: 0 | M17: =K17-L17+M16 -> 18765 | O17: 0 | P17: 0 | Q17: =O17-P17+Q16 -> 0
A18: 7 | C18: مخالفات وقوف على 3656 + 4383 | K18: 0 | L18: 200 | M18: =K18-L18+M17 -> 18565 | O18: 0 | P18: 0 | Q18: =O18-P18+Q17 -> 0
A19: 8 | B19: 44782 | C19: تحويل قيمة مخالفتين | K19: 200 | L19: 0 | M19: =K19-L19+M18 -> 18765 | O19: 0 | P19: 0 | Q19: =O19-P19+Q18 -> 0
A20: 9 | B20: 44814 | C20: كاش الى ابوبيان تحت الحساب | K20: 3000 | L20: 0 | M20: =K20-L20+M19 -> 21765 | O20: 0 | P20: 0 | Q20: =O20-P20+Q19 -> 0
A21: 10 | C21: تم اقفال الحساب بينه وبين ابوبيان | M21: 0 | O21: 0 | P21: 0 | Q21: =O21-P21+Q20 -> 0
A22: 11 | C22: مستحقات من 6 / 1443 الى 6 / 1444 | M22: =K22-L22+M21 -> 0 | O22: 0 | P22: =500*12 -> 6000 | Q22: =O22-P22+Q21 -> -6000
A23: 12 | C23: مستحقات من 6 / 1444 الى 6 / 1445 | M23: =K23-L23+M22 -> 0 | O23: 0 | P23: =750*12 -> 9000 | Q23: =O23-P23+Q22 -> -15000
A24: 13 | B24: 45190 | C24: دفعه الى ابوبيان مستحقات الى 5 / 1444 | K24: 0 | L24: 0 | M24: =K24-L24+M23 -> 0 | O24: 4000 | P24: 0 | Q24: =O24-P24+Q23 -> -11000
A25: 14 | C25: مستحقات من 6 / 1445 الى 6 / 1446 | M25: =K25-L25+M24 -> 0 | O25: 0 | P25: =1000*12 -> 12000 | Q25: =O25-P25+Q24 -> -23000
A26: 15 | C26: مبلغ كاش الى ابوبيان | M26: =K26-L26+M25 -> 0 | O26: 7000 | P26: 0 | Q26: =O26-P26+Q25 -> -16000
A27: 16 | B27: 45767 | C27: مستحقات 3 سيارات من 6 / 1446 الى 6 / 1447 | M27: =K27-L27+M26 -> 0 | O27: 0 | P27: 12000 | Q27: =O27-P27+Q26 -> -28000
A28: 17 | B28: 45780 | C28: تحويل على 306 | M28: =K28-L28+M27 -> 0 | O28: 2100 | Q28: =O28-P28+Q27 -> -25900
A29: 18 | M29: =K29-L29+M28 -> 0 | Q29: =O29-P29+Q28 -> -25900
A30: 19 | M30: =K30-L30+M29 -> 0 | Q30: =O30-P30+Q29 -> -25900
A31: 20 | M31: =K31-L31+M30 -> 0 | Q31: =O31-P31+Q30 -> -25900
A32: 21 | M32: =K32-L32+M31 -> 0 | Q32: =O32-P32+Q31 -> -25900
A33: 22 | M33: =K33-L33+M32 -> 0 | Q33: =O33-P33+Q32 -> -25900
A34: 23 | M34: =K34-L34+M33 -> 0 | Q34: =O34-P34+Q33 -> -25900
A35: 24 | M35: =K35-L35+M34 -> 0 | Q35: =O35-P35+Q34 -> -25900
A36: 25 | M36: =K36-L36+M35 -> 0 | Q36: =O36-P36+Q35 -> -25900
A37: 26 | M37: =K37-L37+M36 -> 0 | Q37: =O37-P37+Q36 -> -25900
A38: 27 | M38: =K38-L38+M37 -> 0 | Q38: =O38-P38+Q37 -> -25900
A39: 28 | M39: =K39-L39+M38 -> 0 | Q39: =O39-P39+Q38 -> -25900
A40: 29 | M40: =K40-L40+M39 -> 0 | Q40: =O40-P40+Q39 -> -25900
... A111: 100 | M111: =K111-L111+M110 -> 0 | Q111: =O111-P111+Q110 -> -25900

Sheet 10
A2: الاسم | B2: سالم الحميدي | D2: الجوال | E2: 0530232275 | G2: طبيعة العمل | H2: سائق شاحنة له | J2: ملاحظات | K2: ليس على الكفاله / لديه 2 شاحنة على اسطول الخليج
A4: الاقامه | B4: 2244737371 | D4: بداية | E4: 44585 | G4: من طرف | H4: أبو عبدالله السوري
A6: السيارة | B6: 3010 / 8827 | D6: شهريا | E6: 700 | G6: مسدد الى تاريخ | H6: 45778
A8: كشف السائقين | K8: =SUM(K12:K111) -> 6850 | L8: =SUM(L12:L111) -> 6850 | M8: =K8-L8 -> 0 | O8: =SUM(O12:O111) -> 20100 | P8: =SUM(P12:P111) -> 23800 | Q8: =O8-P8 -> -3700
K10: خدمات عامة | O10: مستحقات
A11: م | B11: التاريخ | C11: البيان | K11: دائن | L11: مدين | M11: الرصيد | O11: دائن | P11: مدين | Q11: الرصيد
A12: 1 | B12: 44378 | C12: رسوم سنوية من 01 / 8 / 1443 الى 01 / 08 / 1444 | K12: 0 | L12: 0 | M12: =K12-L12 -> 0 | O12: 0 | P12: =350*12 -> 4200 | Q12: =O12-P12 -> -4200
A13: 2 | B13: 44696 | C13: دفعه من رسوم سنوية من 01 / 8 / 1443 الى 01 / 08 / 1444 | K13: 0 | L13: 0 | M13: =K13-L13+M12 -> 0 | O13: 3000 | P13: 0 | Q13: =O13-P13+Q12 -> -1200
A14: 3 | B14: 44848 | C14: تحويل على 110 قيمة كارت تشغيل + اقفال مستحقات الى 01 / 08 / 1444 | K14: 150 | L14: 150 | M14: =K14-L14+M13 -> 0 | O14: 1200 | P14: 0 | Q14: =O14-P14+Q13 -> 0
A15: 4 | B15: 44951 | C15: رسوم سنوية من 01 / 8 / 1444 الى 01 / 08 / 1445 | K15: 0 | L15: 0 | M15: =K15-L15+M14 -> 0 | O15: 0 | P15: =350*12 -> 4200 | Q15: =O15-P15+Q14 -> -4200
A16: 5 | B16: 44953 | C16: دفعه 6 شهور من مستحقات الى تاريخ 1 / 2 / 1445 | K16: 0 | L16: 0 | M16: =K16-L16+M15 -> 0 | O16: 2100 | P16: 0 | Q16: =O16-P16+Q15 -> -2100
A17: 6 | B17: 45182 | C17: قيمة تجديد كارت تشغيل | K17: 150 | L17: 150 | M17: =K17-L17+M16 -> 0 | O17: 0 | P17: 0 | Q17: =O17-P17+Q16 -> -2100
A18: 7 | B18: 45405 | C18: دفعه 6 شهور من مستحقات الى تاريخ 1 / 08 / 1445 | K18: 0 | L18: 0 | M18: =K18-L18+M17 -> 0 | O18: 2000 | P18: 0 | Q18: =O18-P18+Q17 -> -100
A19: 8 | B19: 45405 | C19: رسوم سنوية من 01 / 8 / 1445 الى 01 / 06 / 1446 | K19: 0 | L19: 0 | M19: =K19-L19+M18 -> 0 | O19: 0 | P19: =350*10 -> 3500 | Q19: =O19-P19+Q18 -> -3600
A20: 9 | B20: 45563 | C20: دفعه 6 شهور من مستحقات الى تاريخ 1 / 02 / 1446 | K20: 0 | L20: 0 | M20: =K20-L20+M19 -> 0 | O20: 2100 | P20: 0 | Q20: =O20-P20+Q19 -> -1500
A21: 10 | B21: 45638 | C21: تم تسجيل راس 8827 تاريخ 1 / 6 / 1446 | M21: =K21-L21+M20 -> 0 | Q21: =O21-P21+Q20 -> -1500
A22: 11 | B22: 45638 | C22: رسوم سنوية من 12 / 2024 الى 11 / 2025 | M22: =K22-L22+M21 -> 0 | P22: =11*700 -> 7700 | Q22: =O22-P22+Q21 -> -9200
A23: 12 | B23: 45641 | C23: مستحقات راس 3010 الى 1 / 6 / 1446 + مستحقات 2 راس الى 5 / 2025 / خصم من مطالبة الراجحي محوله على حساب جدة الراجحي | M23: =K23-L23+M22 -> 0 | O23: 5100 | P23: 0 | Q23: =O23-P23+Q22 -> -4100
A24: 13 | B24: 45735 | C24: مبلغ مطالبه 3400 ( مخالفه وثيقة 3000 + 400 مستحقات ) | K24: 3000 | L24: 3000 | M24: =K24-L24+M23 -> 0 | O24: 400 | Q24: =O24-P24+Q23 -> -3700
A25: 14 | B25: 45968 | C25: تحويل على 306 مستحقات سيارتين الى 1 / 11 / 2025+ تامين 3010 مبلغ 3450 + خطاب تنازل 8827 مبلغ 100 | K25: =3450+100 -> 3550 | L25: =3450+100 -> 3550 | M25: =K25-L25+M24 -> 0 | O25: 4200 | Q25: =O25-P25+Q24 -> 500
A26: 15 | B26: 45968 | C26: مستحقات راس 3010 من 1 / 11 / 2025 الى 1 / 11 / 2026 | M26: =K26-L26+M25 -> 0 | P26: =350*12 -> 4200 | Q26: =O26-P26+Q25 -> -3700
A27: 16 | M27: =K27-L27+M26 -> 0 | Q27: =O27-P27+Q26 -> -3700
A28: 17 | M28: =K28-L28+M27 -> 0 | Q28: =O28-P28+Q27 -> -3700
A29: 18 | M29: =K29-L29+M28 -> 0 | Q29: =O29-P29+Q28 -> -3700
A30: 19 | M30: =K30-L30+M29 -> 0 | Q30: =O30-P30+Q29 -> -3700
A31: 20 | M31: =K31-L31+M30 -> 0 | Q31: =O31-P31+Q30 -> -3700
A32: 21 | M32: =K32-L32+M31 -> 0 | Q32: =O32-P32+Q31 -> -3700
A33: 22 | M33: =K33-L33+M32 -> 0 | Q33: =O33-P33+Q32 -> -3700
A34: 23 | M34: =K34-L34+M33 -> 0 | Q34: =O34-P34+Q33 -> -3700
A35: 24 | M35: =K35-L35+M34 -> 0 | Q35: =O35-P35+Q34 -> -3700
A36: 25 | M36: =K36-L36+M35 -> 0 | Q36: =O36-P36+Q35 -> -3700
A37: 26 | M37: =K37-L37+M36 -> 0 | Q37: =O37-P37+Q36 -> -3700
A38: 27 | M38: =K38-L38+M37 -> 0 | Q38: =O38-P38+Q37 -> -3700
... A111: 100 | M111: =K111-L111+M110 -> 0 | Q111: =O111-P111+Q110 -> -3700

Sheet 11
A3: الاسم | B3: عبده دقماق | D3: الجوال | E3: 0507318797 | G3: طبيعة العمل | H3: سائق شاحنة له | J3: ملاحظات | K3: ليس على الكفاله / لديه شاحنة على اسطول الخليج
A5: الاقامه | B5: 2304733724 | D5: بداية | E5: 44594 | G5: من طرف | H5: محمد اطرش
A7: السيارة | B7: 5019 | D7: شهريا | E7: 400 | G7: مسدد الى تاريخ | H7: 45746
A9: كشف السائقين | K9: =SUM(K13:K112) -> 6500 | L9: =SUM(L13:L112) -> 6500 | M9: =K9-L9 -> 0 | O9: =SUM(O13:O112) -> 15500 | P9: =SUM(P13:P112) -> 15500 | Q9: =O9-P9 -> 0
K11: خدمات عامة | O11: مستحقات
A12: م | B12: التاريخ | C12: البيان | K12: دائن | L12: مدين | M12: الرصيد | O12: دائن | P12: مدين | Q12: الرصيد
A13: 1 | C13: دفعة تحت الحساب | K13: 3300 | L13: 0 | M13: =K13-L13 -> 3300 | O13: 0 | P13: 0 | Q13: =O13-P13 -> 0
A14: 2 | C14: رسوم نقل | K14: 0 | L14: 300 | M14: =K14-L14+M13 -> 3000 | O14: 0 | P14: 0 | Q14: =O14-P14+Q13 -> 0
A15: 3 | C15: مبايعه | K15: 0 | L15: 500 | M15: =K15-L15+M14 -> 2500 | O15: 0 | P15: 0 | Q15: =O15-P15+Q14 -> 0
A16: 4 | C16: اتعاب | K16: 0 | L16: 300 | M16: =K16-L16+M15 -> 2200 | O16: 0 | P16: 0 | Q16: =O16-P16+Q15 -> 0
A17: 5 | C17: تامين | K17: 0 | L17: 2200 | M17: =K17-L17+M16 -> 0 | O17: 0 | P17: 0 | Q17: =O17-P17+Q16 -> 0
A18: 6 | C18: خطاب مصدق | K18: 0 | L18: 100 | M18: =K18-L18+M17 -> -100 | O18: 0 | P18: 0 | Q18: =O18-P18+Q17 -> 0
A19: 7 | C19: استماره بدل فاقد | K19: 0 | L19: 200 | M19: =K19-L19+M18 -> -300 | O19: 0 | P19: 0 | Q19: =O19-P19+Q18 -> 0
A20: 8 | C20: بدل ختم البائع | K20: 0 | L20: 300 | M20: =K20-L20+M19 -> -600 | O20: 0 | P20: 0 | Q20: =O20-P20+Q19 -> 0
A21: 9 | C21: كارت ميزان | K21: 0 | L21: 200 | M21: =K21-L21+M20 -> -800 | O21: 0 | P21: 0 | Q21: =O21-P21+Q20 -> 0
A22: 10 | C22: سداد مديونية | K22: 800 | L22: 0 | M22: =K22-L22+M21 -> 0 | O22: 0 | P22: 0 | Q22: =O22-P22+Q21 -> 0
A23: 11 | C23: رسوم سنوية من 01 / 07 / 1443 الى 01 / 07 / 1444 | K23: 0 | L23: 0 | M23: =K23-L23+M22 -> 0 | O23: 0 | P23: =12*400 -> 4800 | Q23: =O23-P23+Q22 -> -4800
A24: 12 | C24: دفعه كاش قيمة 6 اشهر الى 01 / 01 / 1444 | K24: 0 | L24: 0 | M24: =K24-L24+M23 -> 0 | O24: 2400 | P24: 0 | Q24: =O24-P24+Q23 -> -2400
A25: 13 | B25: 44971 | C25: قيمة تامين و مستحقات الى 1 / 7 / 1444 من النمله على ح 306 اجمالي 4800 | K25: 2400 | L25: 2400 | M25: =K25-L25+M24 -> 0 | O25: 2400 | P25: 0 | Q25: =O25-P25+Q24 -> 0
A26: 14 | B26: 45015 | C26: رسوم سنوية من 01 / 07 / 1444 الى 01 / 07 / 1445 | K26: 0 | L26: 0 | M26: =K26-L26+M25 -> 0 | O26: 0 | P26: =12*400 -> 4800 | Q26: =O26-P26+Q25 -> -4800
A27: 15 | B27: 45240 | C27: دفعه كاش قيمة 3 شهور الى 01 / 10 / 1444 | K27: 0 | L27: 0 | M27: =K27-L27+M26 -> 0 | O27: 1200 | P27: 0 | Q27: =O27-P27+Q26 -> -3600
A28: 16 | B28: 45270 | C28: دفعه كاش قيمة 3 شهور الى 01 / 01 / 1445 | K28: 0 | L28: 0 | M28: =K28-L28+M27 -> 0 | O28: 1200 | P28: 0 | Q28: =O28-P28+Q27 -> -2400
A29: 17 | B29: 45369 | C29: دفعه كاش قيمة شهرين الى 01 / 03 / 1445 | K29: 0 | L29: 0 | M29: =K29-L29+M28 -> 0 | O29: 800 | P29: 0 | Q29: =O29-P29+Q28 -> -1600
A30: 18 | B30: 45369 | C30: رسوم سنوية من 01 / 07 / 1445 الى 01 / 07 / 1446 | K30: 0 | L30: 0 | M30: =K30-L30+M29 -> 0 | O30: 0 | P30: =400*12 -> 4800 | Q30: =O30-P30+Q29 -> -6400
A31: 19 | B31: 45369 | C31: رسوم سنوية من 01 / 07 / 1446 الى 01 / 10 / 1446 | M31: =K31-L31+M30 -> 0 | P31: =400*3 -> 1200 | Q31: =O31-P31+Q30 -> -7600
A32: 20 | B32: 45726 | C32: كاش الى ابوبيان مستحقات الى 1 / 10 / 1446 / تم خصم 100 ريال من ابوبيان | M32: =K32-L32+M31 -> 0 | O32: 7500 | P32: -100 | Q32: =O32-P32+Q31 -> 0
A33: 21 | C33: تم نقل ملكية السياره | M33: =K33-L33+M32 -> 0 | O33: 0 | P33: 0 | Q33: =O33-P33+Q32 -> 0
A34: 22 | M34: =K34-L34+M33 -> 0 | O34: 0 | P34: 0 | Q34: =O34-P34+Q33 -> 0
A35: 23 | M35: =K35-L35+M34 -> 0 | O35: 0 | P35: 0 | Q35: =O35-P35+Q34 -> 0
A36: 24 | M36: =K36-L36+M35 -> 0 | O36: 0 | P36: 0 | Q36: =O36-P36+Q35 -> 0
A37: 25 | M37: =K37-L37+M36 -> 0 | O37: 0 | P37: 0 | Q37: =O37-P37+Q36 -> 0
A38: 26 | M38: =K38-L38+M37 -> 0 | O38: 0 | P38: 0 | Q38: =O38-P38+Q37 -> 0
A39: 27 | M39: =K39-L39+M38 -> 0 | O39: 0 | P39: 0 | Q39: =O39-P39+Q38 -> 0
A40: 28 | M40: =K40-L40+M39 -> 0 | O40: 0 | P40: 0 | Q40: =O40-P40+Q39 -> 0
A41: 29 | M41: =K41-L41+M40 -> 0 | O41: 0 | P41: 0 | Q41: =O41-P41+Q40 -> 0
A42: 30 | M42: =K42-L42+M41 -> 0 | O42: 0 | P42: 0 | Q42: =O42-P42+Q41 -> 0
A43: 31 | M43: =K43-L43+M42 -> 0 | O43: 0 | P43: 0 | Q43: =O43-P43+Q42 -> 0
A44: 32 | M44: =K44-L44+M43 -> 0 | O44: 0 | P44: 0 | Q44: =O44-P44+Q43 -> 0
A45: 33 | M45: =K45-L45+M44 -> 0 | O45: 0 | P45: 0 | Q45: =O45-P45+Q44 -> 0
... A112: 100 | M112: =K112-L112+M111 -> 0 | O112: 0 | P112: 0 | Q112: =O112-P112+Q111 -> 0

Sheet 15
A2: الاسم | B2: محمد مثنى | D2: الجوال | E2: 0556805501 | G2: طبيعة العمل | H2: نقل مؤقت | J2: ملاحظات | K2: على الكفاله / نقل مؤقت لحين الحصول على عمل
